---
layout: post
title: "로그 파일 및 에러 해결"
date: 2023-12-12
tags: [및, 파일, 로그, 해결, 에러]
categories: blog
---

## 사용자 입력:
> 인텔리제이에서 실행시켰을 때, 에러 . C:\git\python-rtde\venv\Scripts\python.exe C:\git\python-rtde\xml2db.py -db oracle+oracledb://LIAUSR4:LIAUSR4@192.168.2.69:1521/oracle 
C:\git\python-rtde\rtde\java-lib\bcprov-jdk18on-177.jar;C:\git\python-rtde\rtde\java-lib\lia-ds-cosec.jar
Traceback (most recent call last):
  File "C:\Program Files\Python310\lib\logging\config.py", line 565, in configure
    handler = self.configure_handler(handlers[name])
  File "C:\Program Files\Python310\lib\logging\config.py", line 746, in configure_handler
    result = factory(**kwargs)
  File "C:\Program Files\Python310\lib\logging\__init__.py", line 1169, in __init__
    StreamHandler.__init__(self, self._open())
  File "C:\Program Files\Python310\lib\logging\__init__.py", line 1201, in _open
    return open_func(self.baseFilename, self.mode,
FileNotFoundError: [Errno 2] No such file or directory: 'C:\\git\\python-rtde\\log\\error.log'

The above exception was the direct cause of the following exception:

Traceback (most recent call last):
  File "C:\git\python-rtde\xml2db.py", line 321, in <module>
    logger = set_log('./logging.yaml', 'xml2db')
  File "C:\git\python-rtde\rtde\util.py", line 218, in set_log
    logging.config.dictConfig(getlogConf(yaml_location))
  File "C:\Program Files\Python310\lib\logging\config.py", line 811, in dictConfig
    dictConfigClass(config).configure()
  File "C:\Program Files\Python310\lib\logging\config.py", line 572, in configure
    raise ValueError('Unable to configure handler '
ValueError: Unable to configure handler 'error_file'

During handling of the above exception, another exception occurred:

Traceback (most recent call last):
  File "C:\git\python-rtde\xml2db.py", line 351, in <module>
    logger.error(e)
NameError: name 'logger' is not defined


## ChatGPT 응답:
> The error you're encountering in IntelliJ IDEA when running your Python script (`xml2db.py`) seems to stem from a few key issues related to logging configuration and file paths. Let's break down the errors and suggest solutions:

1. **FileNotFoundError for 'error.log'**:
   - The script is trying to open or create a log file at `'C:\git\python-rtde\log\error.log'`, but it can't find the specified path.
   - **Solution**: Ensure that the directory `C:\git\python-rtde\log` exists. If it doesn't, you need to create it. Alternatively, you can modify your logging configuration to point to an existing directory.

2. **ValueError: Unable to configure handler 'error_file'**:
   - This is likely caused by the previous error. The logging configuration is trying to set up a handler named 'error_file', which probably writes to the `error.log` file. Since the file can't be found or opened, configuring this handler fails.
   - **Solution**: After ensuring the log file's directory exists (or changing the path), this error should be resolved.

3. **NameError: name 'logger' is not defined**:
   - This error occurs in the exception handling block. It seems like the script attempts to log an error when another exception is caught, but the `logger` object is not defined or accessible in that scope.
   - **Solution**: Ensure that the `logger` object is initialized and accessible in the scope where it's being used. It might involve structuring your logging setup and exception handling differently.

Here's a general approach to addressing these issues:

- **Check Logging Configuration**: Make sure your `logging.yaml` file is correctly set up and points to valid file paths.
- **File Paths and Permissions**: Ensure all specified paths in your logging configuration exist and that your application has the necessary permissions to write to those paths.
- **Exception Handling**: Initialize your `logger` before you might encounter exceptions, or use a different method to handle exceptions if the logger isn't available.

If you've made these changes and are still facing issues, you might want to verify the rest of your script for any other potential problems, or consider the environment settings in IntelliJ IDEA.

## 사용자 입력:
> 한글로

## ChatGPT 응답:
> 당신이 IntelliJ IDEA에서 Python 스크립트(`xml2db.py`)를 실행할 때 발생하는 오류는 로깅 구성과 파일 경로와 관련된 몇 가지 주요 문제로 인한 것으로 보입니다. 오류를 분석하여 해결책을 제시해보겠습니다.

1. **'error.log'에 대한 FileNotFoundError**:
   - 스크립트는 `'C:\git\python-rtde\log\error.log'` 위치에서 로그 파일을 열거나 생성하려고 하지만, 지정된 경로를 찾을 수 없습니다.
   - **해결책**: `C:\git\python-rtde\log` 디렉토리가 존재하는지 확인하세요. 존재하지 않으면 생성해야 합니다. 또는 로깅 구성을 수정하여 기존 디렉토리를 가리키도록 변경할 수 있습니다.

2. **ValueError: 'error_file' 핸들러 구성 불가**:
   - 이 오류는 이전 오류로 인해 발생할 가능성이 높습니다. 로깅 구성은 'error_file'이라는 핸들러를 설정하려고 하는데, 이 핸들러는 아마도 `error.log` 파일에 쓰려고 할 것입니다. 파일을 찾거나 열 수 없으므로 이 핸들러를 구성하는 데 실패합니다.
   - **해결책**: 로그 파일의 디렉토리가 존재하거나(또는 경로를 변경한 후) 이 오류는 해결되어야 합니다.

3. **NameError: 'logger' 이름이 정의되지 않음**:
   - 이 오류는 예외 처리 블록에서 발생합니다. 스크립트는 다른 예외가 잡힐 때 오류를 로깅하려고 시도하는 것 같지만, `logger` 객체가 해당 범위에서 정의되지 않았거나 접근할 수 없습니다.
   - **해결책**: `logger` 객체가 사용되는 범위에서 초기화되고 접근 가능하도록 확인하세요. 이는 로깅 설정과 예외 처리를 다르게 구조화하는 것을 포함할 수 있습니다.

이 문제들을 해결하기 위한 일반적인 접근 방법은 다음과 같습니다:

- **로깅 구성 확인**: `logging.yaml` 파일이 올바르게 설정되어 있고 유효한 파일 경로를 가리키고 있는지 확인하세요.
- **파일 경로 및 권한**: 로깅 구성에서 지정된 모든 경로가 존재하고 애플리케이션이 해당 경로에 쓸 수 있는 필요한 권한을 가지고 있는지 확인하세요.
- **예외 처리**: 예외를 만날 수 있는 경우에 `logger`를 초기화하거나, 로거가 사용 가능하지 않은 경우 다른 방법으로 예외를 처리하세요.

이러한 변경을 한 후에도 여전히 문제가 발생한다면, 스크립트의 다른 잠재적인 문제를 확인하거나 IntelliJ IDEA의 환경 설정을 검토해야 할 수도 있습니다.

